Workbook

Sheet Raw Data
A1: OrderID | B1: OrderDate | C1: Region | D1: Product | E1: Customer | F1: SalesRep | G1: Quantity | H1: UnitPrice
A2: 1352 | B2: 04/20/2025 | C2: WEST | D2: webcam hd | E2: Customer 14 | F2: Karthik | G2: 3 | H2: 1355.11
A3: 1130 | B3: 03/31/2025 | C3: East | D3: Mechanical Keyboard | E3: Customer 46 | F3: Priya | G3: -1 | H3: 1598.94
A4: 1356 | B4: 2025-05-22 | C4: north | D4: Laptop Stand | E4: Customer 42 | F4: Meena | G4: 5 | H4: 464.06
A5: 1103 | B5: 17/06/2025 | C5: east | D5: usb-c cable | E5: Customer 9 | F5: Suresh | G5: 2 | H5: 1499.54
A6: 1310 | B6: 01/21/2025 | C6: South | D6: USB-C Cable | E6: Customer 6 | F6: Meena | G6: 4
A7: 1015 | B7: 13/02/2025 | C7: South | D7: Mechanical Keyboard | E7: Customer 50 | F7: Priya | G7: 3 | H7: 1989.12
A8: 1392 | B8: 25/01/2025 | C8: west | D8: Mechanical Keyboard | E8: Customer 50 | F8: Priya | G8: 0 | H8: 522
A9: 1306 | B9: 13-02-2025 | C9: east | D9: webcam hd | E9: Customer 53 | F9: Divya | G9: 2 | H9: 1519.33
A10: 1016 | B10: 08/05/2025 | C10: WEST | D10: Desk Lamp | E10: Customer 20 | F10: Divya | G10: 2 | H10: 1078.84
A11: 1105 | B11: 2025-07-23 | C11: South | D11: Bluetooth Speaker | E11: Customer 1 | F11: Karthik | G11: -1 | H11: 296.3
A12: 1204 | B12: 2025-09-21 | D12: Bluetooth Speaker | E12: Customer 43 | F12: Arun | G12: five | H12: 496.75
A13: 1088 | B13: 2025-06-24 | C13: north | D13: Laptop Stand | E13: Customer 47 | F13: Karthik | G13: 0 | H13: 1648.57
A14: 1061 | B14: 04-06-2025 | C14: north | D14: Laptop stand | E14: Customer 35 | F14: Divya | G14: 2 | H14: 299.36
A15: 1228 | B15: 06/13/2025 | C15: South | D15: Laptop stand | E15: Customer 27 | F15: Arun | G15: 0 | H15: 2831.82
A16: 1237 | B16: 13/09/2025 | C16: South | D16: Webcam HD | E16: Customer 55 | F16: Arun | G16: -1 | H16: 282.84
A17: 1137 | B17: 04/02/2025 | C17: west | D17: webcam hd | E17: Customer 20 | F17: Karthik | G17: 0 | H17: 290.15
A18: 1114 | B18: 01/14/2025 | C18: north | D18: Laptop stand | E18: Customer 51 | F18: Priya | G18: 0 | H18: 721.62
A19: 1112 | B19: 2025-01-26 | C19: WEST | D19: USB-C Cable | E19: Customer 51 | F19: Suresh | G19: 4 | H19: 318.72
A20: 1301 | B20: 01/27/2025 | C20: WEST | D20: Mechanical Keyboard | E20: Customer 3 | F20: Divya | G20: 2 | H20: 1072.13
A21: 1348 | B21: 23-03-2025 | C21: north | D21: Desk Lamp | E21: Customer 33 | F21: Divya | G21: five | H21: 3209.71
A22: 1102 | B22: 12-03-2025 | C22: north | D22: Laptop Stand | E22: Customer 51 | F22: Divya | G22: 1 | H22: 1458.49
A23: 1296 | B23: 05/13/2025 | C23: South | D23: USB-C Cable | E23: Customer 48 | F23: Karthik | G23: 2 | H23: 3238.86
A24: 1194 | B24: 16/05/2025 | C24: WEST | D24: usb-c cable | E24: Customer 18 | F24: Suresh | G24: 5 | H24: 543.06
... A29: 1128 | B29: 2025-02-28 | C29: East | D29: wireless mouse | E29: Customer 19 | F29: Meena | G29: 0 | H29: 1004.38
A30: 1321 | B30: 2025-01-15 | C30: east | D30: Webcam HD | E30: Customer 13 | F30: Divya | G30: -1
A31: 1127 | B31: 26-01-2025 | C31: north | D31: bluetooth speaker | E31: Customer 43 | F31: Divya | H31: 1481.62
A32: 1326 | B32: 2025-07-13 | C32: north | D32: USB-C Cable | E32: Customer 12 | F32: Meena | G32: 1 | H32: 2178.39
A33: 1291 | B33: 07-02-2025 | C33: South | D33: Wireless Mouse | E33: Customer 17 | F33: Priya | G33: 1 | H33: 325.83
A34: 1209 | B34: 11/02/2025 | C34: South | D34: wireless mouse | E34: Customer 59 | F34: Suresh | G34: 2 | H34: 318.66
A35: 1073 | B35: 2025-03-18 | C35: South | D35: usb-c cable | E35: Customer 8 | F35: Suresh | G35: 3 | H35: 1527.82
A36: 1144 | B36: 07-03-2025 | C36: East | D36: Mechanical Keyboard | E36: Customer 24 | F36: Arun | G36: 2 | H36: 747.91
A37: 1193 | B37: 27/09/2025 | C37: South | D37: USB-C Cable | E37: Customer 30 | F37: Suresh | G37: 2 | H37: 1455.32
A38: 1211 | B38: 29/01/2025 | C38: east | D38: Mechanical Keyboard | E38: Customer 27 | F38: Divya | G38: 0 | H38: 302.52
A39: 1124 | B39: 2025-01-14 | C39: north | D39: USB-C Cable | E39: Customer 18 | F39: Meena | G39: 5 | H39: 775.19
A40: 1359 | B40: 2025-09-17 | C40: east | D40: webcam hd | E40: Customer 57 | F40: Suresh | G40: 3 | H40: 734.7
A41: 1056 | B41: 19/04/2025 | C41: South | D41: Laptop stand | E41: Customer 49 | F41: Divya | G41: 5 | H41: 3269.63
A42: 1067 | B42: 2025-05-05 | C42: South | D42: bluetooth speaker | E42: Customer 36 | F42: Suresh | G42: 2 | H42: 1098.23
A43: 1373 | B43: 23-02-2025 | C43: north | D43: wireless mouse | E43: Customer 51 | F43: Arun | H43: 509.88
A44: 1260 | B44: 2025-01-12 | C44: South | D44: webcam hd | E44: Customer 52 | F44: Priya | G44: 4 | H44: 1401.4
...

Sheet Cleaned Data
A1: OrderID | B1: OrderDate | C1: Region | D1: Product | E1: Customer | F1: SalesRep | G1: Quantity | H1: UnitPrice | I1: Revenue | J1: Month
A2: 1000 | B2: 2025-02-27 | C2: North | D2: Usb-C Cable | E2: Customer 15 | F2: Priya | G2: 2 | H2: 2095.22 | I2: 4190.44 | J2: 2025-02
A3: 1002 | B3: 2025-08-03 | C3: West | D3: Webcam Hd | E3: Customer 18 | F3: Arun | G3: 3 | H3: 1968.06 | I3: 5904.18 | J3: 2025-08
A4: 1005 | B4: 2025-04-27 | C4: South | D4: Usb-C Cable | E4: Customer 56 | F4: Arun | G4: 3 | H4: 791.55 | I4: 2374.65 | J4: 2025-04
A5: 1006 | B5: 2025-07-01 | C5: North | D5: Desk Lamp | E5: Customer 60 | F5: Meena | G5: 2 | H5: 1539.47 | I5: 3078.94 | J5: 2025-07
A6: 1007 | B6: 2025-08-25 | C6: North | D6: Webcam Hd | E6: Customer 45 | F6: Suresh | G6: 4 | H6: 1928.75 | I6: 7715 | J6: 2025-08
A7: 1010 | B7: 2025-07-24 | C7: West | D7: Usb-C Cable | E7: Customer 33 | F7: Divya | G7: 2 | H7: 2727.36 | I7: 5454.72 | J7: 2025-07
A8: 1011 | B8: 2025-05-08 | C8: East | D8: Bluetooth Speaker | E8: Customer 39 | F8: Divya | G8: 5 | H8: 874.28 | I8: 4371.4 | J8: 2025-05
A9: 1012 | B9: 2025-02-28 | C9: South | D9: Wireless Mouse | E9: Customer 19 | F9: Divya | G9: 3 | H9: 899.75 | I9: 2699.25 | J9: 2025-02
A10: 1014 | B10: 2025-01-01 | C10: West | D10: Wireless Mouse | E10: Customer 8 | F10: Karthik | G10: 5 | H10: 454.88 | I10: 2274.4 | J10: 2025-01
A11: 1015 | B11: 2025-02-13 | C11: South | D11: Mechanical Keyboard | E11: Customer 50 | F11: Priya | G11: 3 | H11: 1989.12 | I11: 5967.36 | J11: 2025-02
A12: 1016 | B12: 2025-08-05 | C12: West | D12: Desk Lamp | E12: Customer 20 | F12: Divya | G12: 2 | H12: 1078.84 | I12: 2157.68 | J12: 2025-08
A13: 1018 | B13: 2025-04-02 | C13: South | D13: Wireless Mouse | E13: Customer 33 | F13: Priya | G13: 5 | H13: 1993.17 | I13: 9965.85 | J13: 2025-04
... A254: 1399 | B254: 2025-02-22 | C254: East | D254: Usb-C Cable | E254: Customer 33 | F254: Meena | G254: 5 | H254: 2064.76 | I254: 10323.8 | J254: 2025-02

Sheet Pivot - Region
A1: Region | B1: Total Revenue | C1: Units Sold | D1: Orders | E1: Avg Order Value
A2: East | B2: =SUMIFS('Cleaned Data'!$I$2:$I$254,'Cleaned Data'!$C$2:$C$254,$A2) -> 200270.53 | C2: =SUMIFS('Cleaned Data'!$G$2:$G$254,'Cleaned Data'!$C$2:$C$254,$A2) -> 173 | D2: =COUNTIFS('Cleaned Data'!$C$2:$C$254,$A2) -> 63 | E2: =IFERROR(B2/D2,0) -> 3178.8973
A3: North | B3: =SUMIFS('Cleaned Data'!$I$2:$I$254,'Cleaned Data'!$C$2:$C$254,$A3) -> 254210.33 | C3: =SUMIFS('Cleaned Data'!$G$2:$G$254,'Cleaned Data'!$C$2:$C$254,$A3) -> 196 | D3: =COUNTIFS('Cleaned Data'!$C$2:$C$254,$A3) -> 66 | E3: =IFERROR(B3/D3,0) -> 3851.6717
A4: South | B4: =SUMIFS('Cleaned Data'!$I$2:$I$254,'Cleaned Data'!$C$2:$C$254,$A4) -> 231473.43 | C4: =SUMIFS('Cleaned Data'!$G$2:$G$254,'Cleaned Data'!$C$2:$C$254,$A4) -> 192 | D4: =COUNTIFS('Cleaned Data'!$C$2:$C$254,$A4) -> 62 | E4: =IFERROR(B4/D4,0) -> 3733.4424
A5: Unknown | B5: =SUMIFS('Cleaned Data'!$I$2:$I$254,'Cleaned Data'!$C$2:$C$254,$A5) -> 23417.65 | C5: =SUMIFS('Cleaned Data'!$G$2:$G$254,'Cleaned Data'!$C$2:$C$254,$A5) -> 17 | D5: =COUNTIFS('Cleaned Data'!$C$2:$C$254,$A5) -> 7 | E5: =IFERROR(B5/D5,0) -> 3345.3786
A6: West | B6: =SUMIFS('Cleaned Data'!$I$2:$I$254,'Cleaned Data'!$C$2:$C$254,$A6) -> 279619.08 | C6: =SUMIFS('Cleaned Data'!$G$2:$G$254,'Cleaned Data'!$C$2:$C$254,$A6) -> 191 | D6: =COUNTIFS('Cleaned Data'!$C$2:$C$254,$A6) -> 55 | E6: =IFERROR(B6/D6,0) -> 5083.9833
A7: Total | B7: =SUM(B2:B6) -> 988991.02 | C7: =SUM(C2:C6) -> 769 | D7: =SUM(D2:D6) -> 253 | E7: =IFERROR(B7/D7,0) -> 3909.0554

Sheet Pivot - Product
A1: Product | B1: Total Revenue | C1: Units Sold | D1: Orders | E1: Avg Order Value
A2: Bluetooth Speaker | B2: =SUMIFS('Cleaned Data'!$I$2:$I$254,'Cleaned Data'!$D$2:$D$254,$A2) -> 124047.63 | C2: =SUMIFS('Cleaned Data'!$G$2:$G$254,'Cleaned Data'!$D$2:$D$254,$A2) -> 107 | D2: =COUNTIFS('Cleaned Data'!$D$2:$D$254,$A2) -> 34 | E2: =IFERROR(B2/D2,0) -> 3648.4597
A3: Desk Lamp | B3: =SUMIFS('Cleaned Data'!$I$2:$I$254,'Cleaned Data'!$D$2:$D$254,$A3) -> 110522.55 | C3: =SUMIFS('Cleaned Data'!$G$2:$G$254,'Cleaned Data'!$D$2:$D$254,$A3) -> 75 | D3: =COUNTIFS('Cleaned Data'!$D$2:$D$254,$A3) -> 26 | E3: =IFERROR(B3/D3,0) -> 4250.8673
A4: Laptop Stand | B4: =SUMIFS('Cleaned Data'!$I$2:$I$254,'Cleaned Data'!$D$2:$D$254,$A4) -> 133954.72 | C4: =SUMIFS('Cleaned Data'!$G$2:$G$254,'Cleaned Data'!$D$2:$D$254,$A4) -> 114 | D4: =COUNTIFS('Cleaned Data'!$D$2:$D$254,$A4) -> 37 | E4: =IFERROR(B4/D4,0) -> 3620.3978
A5: Mechanical Keyboard | B5: =SUMIFS('Cleaned Data'!$I$2:$I$254,'Cleaned Data'!$D$2:$D$254,$A5) -> 92715.06 | C5: =SUMIFS('Cleaned Data'!$G$2:$G$254,'Cleaned Data'!$D$2:$D$254,$A5) -> 78 | D5: =COUNTIFS('Cleaned Data'!$D$2:$D$254,$A5) -> 27 | E5: =IFERROR(B5/D5,0) -> 3433.8911
A6: Usb-C Cable | B6: =SUMIFS('Cleaned Data'!$I$2:$I$254,'Cleaned Data'!$D$2:$D$254,$A6) -> 178455.94 | C6: =SUMIFS('Cleaned Data'!$G$2:$G$254,'Cleaned Data'!$D$2:$D$254,$A6) -> 124 | D6: =COUNTIFS('Cleaned Data'!$D$2:$D$254,$A6) -> 43 | E6: =IFERROR(B6/D6,0) -> 4150.1381
A7: Webcam Hd | B7: =SUMIFS('Cleaned Data'!$I$2:$I$254,'Cleaned Data'!$D$2:$D$254,$A7) -> 183762.44 | C7: =SUMIFS('Cleaned Data'!$G$2:$G$254,'Cleaned Data'!$D$2:$D$254,$A7) -> 157 | D7: =COUNTIFS('Cleaned Data'!$D$2:$D$254,$A7) -> 51 | E7: =IFERROR(B7/D7,0) -> 3603.1851
A8: Wireless Mouse | B8: =SUMIFS('Cleaned Data'!$I$2:$I$254,'Cleaned Data'!$D$2:$D$254,$A8) -> 165532.68 | C8: =SUMIFS('Cleaned Data'!$G$2:$G$254,'Cleaned Data'!$D$2:$D$254,$A8) -> 114 | D8: =COUNTIFS('Cleaned Data'!$D$2:$D$254,$A8) -> 35 | E8: =IFERROR(B8/D8,0) -> 4729.5051
A9: Total | B9: =SUM(B2:B8) -> 988991.02 | C9: =SUM(C2:C8) -> 769 | D9: =SUM(D2:D8) -> 253 | E9: =IFERROR(B9/D9,0) -> 3909.0554

Sheet Pivot - Month
A1: Month | B1: Total Revenue | C1: Units Sold | D1: Orders | E1: Avg Order Value
A2: 2025-01 | B2: =SUMIFS('Cleaned Data'!$I$2:$I$254,'Cleaned Data'!$J$2:$J$254,$A2) -> 126443.26 | C2: =SUMIFS('Cleaned Data'!$G$2:$G$254,'Cleaned Data'!$J$2:$J$254,$A2) -> 106 | D2: =COUNTIFS('Cleaned Data'!$J$2:$J$254,$A2) -> 32 | E2: =IFERROR(B2/D2,0) -> 3951.3519
A3: 2025-02 | B3: =SUMIFS('Cleaned Data'!$I$2:$I$254,'Cleaned Data'!$J$2:$J$254,$A3) -> 74468.48 | C3: =SUMIFS('Cleaned Data'!$G$2:$G$254,'Cleaned Data'!$J$2:$J$254,$A3) -> 68 | D3: =COUNTIFS('Cleaned Data'!$J$2:$J$254,$A3) -> 22 | E3: =IFERROR(B3/D3,0) -> 3384.9309
A4: 2025-03 | B4: =SUMIFS('Cleaned Data'!$I$2:$I$254,'Cleaned Data'!$J$2:$J$254,$A4) -> 117546.8 | C4: =SUMIFS('Cleaned Data'!$G$2:$G$254,'Cleaned Data'!$J$2:$J$254,$A4) -> 82 | D4: =COUNTIFS('Cleaned Data'!$J$2:$J$254,$A4) -> 25 | E4: =IFERROR(B4/D4,0) -> 4701.872
A5: 2025-04 | B5: =SUMIFS('Cleaned Data'!$I$2:$I$254,'Cleaned Data'!$J$2:$J$254,$A5) -> 159138.48 | C5: =SUMIFS('Cleaned Data'!$G$2:$G$254,'Cleaned Data'!$J$2:$J$254,$A5) -> 106 | D5: =COUNTIFS('Cleaned Data'!$J$2:$J$254,$A5) -> 32 | E5: =IFERROR(B5/D5,0) -> 4973.0775
A6: 2025-05 | B6: =SUMIFS('Cleaned Data'!$I$2:$I$254,'Cleaned Data'!$J$2:$J$254,$A6) -> 101656.82 | C6: =SUMIFS('Cleaned Data'!$G$2:$G$254,'Cleaned Data'!$J$2:$J$254,$A6) -> 84 | D6: =COUNTIFS('Cleaned Data'!$J$2:$J$254,$A6) -> 32 | E6: =IFERROR(B6/D6,0) -> 3176.7756
A7: 2025-06 | B7: =SUMIFS('Cleaned Data'!$I$2:$I$254,'Cleaned Data'!$J$2:$J$254,$A7) -> 76278.47 | C7: =SUMIFS('Cleaned Data'!$G$2:$G$254,'Cleaned Data'!$J$2:$J$254,$A7) -> 55 | D7: =COUNTIFS('Cleaned Data'!$J$2:$J$254,$A7) -> 17 | E7: =IFERROR(B7/D7,0) -> 4486.9688
A8: 2025-07 | B8: =SUMIFS('Cleaned Data'!$I$2:$I$254,'Cleaned Data'!$J$2:$J$254,$A8) -> 82422.4 | C8: =SUMIFS('Cleaned Data'!$G$2:$G$254,'Cleaned Data'!$J$2:$J$254,$A8) -> 55 | D8: =COUNTIFS('Cleaned Data'!$J$2:$J$254,$A8) -> 21 | E8: =IFERROR(B8/D8,0) -> 3924.8762
A9: 2025-08 | B9: =SUMIFS('Cleaned Data'!$I$2:$I$254,'Cleaned Data'!$J$2:$J$254,$A9) -> 121597.81 | C9: =SUMIFS('Cleaned Data'!$G$2:$G$254,'Cleaned Data'!$J$2:$J$254,$A9) -> 114 | D9: =COUNTIFS('Cleaned Data'!$J$2:$J$254,$A9) -> 36 | E9: =IFERROR(B9/D9,0) -> 3377.7169
A10: 2025-09 | B10: =SUMIFS('Cleaned Data'!$I$2:$I$254,'Cleaned Data'!$J$2:$J$254,$A10) -> 93588.45 | C10: =SUMIFS('Cleaned Data'!$G$2:$G$254,'Cleaned Data'!$J$2:$J$254,$A10) -> 76 | D10: =COUNTIFS('Cleaned Data'!$J$2:$J$254,$A10) -> 27 | E10: =IFERROR(B10/D10,0) -> 3466.2389
A11: 2025-10 | B11: =SUMIFS('Cleaned Data'!$I$2:$I$254,'Cleaned Data'!$J$2:$J$254,$A11) -> 13103.99 | C11: =SUMIFS('Cleaned Data'!$G$2:$G$254,'Cleaned Data'!$J$2:$J$254,$A11) -> 11 | D11: =COUNTIFS('Cleaned Data'!$J$2:$J$254,$A11) -> 3 | E11: =IFERROR(B11/D11,0) -> 4367.9967
A12: 2025-11 | B12: =SUMIFS('Cleaned Data'!$I$2:$I$254,'Cleaned Data'!$J$2:$J$254,$A12) -> 14119.83 | C12: =SUMIFS('Cleaned Data'!$G$2:$G$254,'Cleaned Data'!$J$2:$J$254,$A12) -> 7 | D12: =COUNTIFS('Cleaned Data'!$J$2:$J$254,$A12) -> 3 | E12: =IFERROR(B12/D12,0) -> 4706.61
A13: 2025-12 | B13: =SUMIFS('Cleaned Data'!$I$2:$I$254,'Cleaned Data'!$J$2:$J$254,$A13) -> 8626.23 | C13: =SUMIFS('Cleaned Data'!$G$2:$G$254,'Cleaned Data'!$J$2:$J$254,$A13) -> 5 | D13: =COUNTIFS('Cleaned Data'!$J$2:$J$254,$A13) -> 3 | E13: =IFERROR(B13/D13,0) -> 2875.41
A14: Total | B14: =SUM(B2:B13) -> 988991.02 | C14: =SUM(C2:C13) -> 769 | D14: =SUM(D2:D13) -> 253 | E14: =IFERROR(B14/D14,0) -> 3909.0554
